<robot name = "robot">
    <link name="Torso">
        <inertial>
            <origin xyz="0 0 1" rpy="0 0 0"/>
            <mass value="1" />
            <inertia ixx="100" ixy="0" ixz="0" iyy="100" iyz="0" izz="100" />
        </inertial>
        <visual>
            <origin xyz="0 0 1" rpy="0 0 0"/>
            <geometry>
                <box size="2 1 0.5" />
            </geometry>
            <material name="Cyan">
                <color rgba="0 1.0 1.0 1.0"/>
            </material>
        </visual>
        <collision>
            <origin xyz="0 0 1" rpy="0 0 0"/>
            <geometry>
                <box size="2 1 0.5" />
            </geometry>
        </collision>
    </link>
    <joint name="Torso_Head" type="revolute">
       <parent link="Torso"/>
       <child  link="Head"/>
       <origin rpy="0 0 0" xyz="1 0 0.5" />
     <axis xyz="1 0 0"/>
       <limit effort="0.0" lower="-3.14159" upper="3.14159" velocity="0.0"/>
    </joint>
    <link name="Head">
        <inertial>
            <origin xyz="0 0 0.5" rpy="0 0 0"/>
            <mass value="1" />
            <inertia ixx="100" ixy="0" ixz="0" iyy="100" iyz="0" izz="100" />
        </inertial>
        <visual>
            <origin xyz="0 0 0.5" rpy="0 0 0"/>
            <geometry>
                <box size="0.5 0.75 0.5" />
            </geometry>
            <material name="Cyan">
                <color rgba="0 1.0 1.0 1.0"/>
            </material>
        </visual>
        <collision>
            <origin xyz="0 0 0.5" rpy="0 0 0"/>
            <geometry>
                <box size="0.5 0.75 0.5" />
            </geometry>
        </collision>
    </link>
    <joint name="Torso_BackLeftShoulder" type="revolute">
       <parent link="Torso"/>
       <child  link="BackLeftShoulder"/>
       <origin rpy="0 0 0" xyz="-0.75 0.5 1.0" />
     <axis xyz="1 0 0"/>
       <limit effort="0.0" lower="-3.14159" upper="3.14159" velocity="0.0"/>
    </joint>
    <link name="BackLeftShoulder">
        <inertial>
            <origin xyz="0 0 0" rpy="0 0 0"/>
            <mass value="1" />
            <inertia ixx="100" ixy="0" ixz="0" iyy="100" iyz="0" izz="100" />
        </inertial>
        <visual>
            <origin xyz="0 0 0" rpy="0 0 0"/>
            <geometry>
                <box size="0.5 0.5 0.5" />
            </geometry>
            <material name="Cyan">
                <color rgba="0 1.0 1.0 1.0"/>
            </material>
        </visual>
        <collision>
            <origin xyz="0 0 0" rpy="0 0 0"/>
            <geometry>
                <box size="0.5 0.5 0.5" />
            </geometry>
        </collision>
    </link>
    <joint name="Torso_BackRightShoulder" type="revolute">
       <parent link="Torso"/>
       <child  link="BackRightShoulder"/>
       <origin rpy="0 0 0" xyz="-0.75 -0.5 1.0" />
     <axis xyz="1 0 0"/>
       <limit effort="0.0" lower="-3.14159" upper="3.14159" velocity="0.0"/>
    </joint>
    <link name="BackRightShoulder">
        <inertial>
            <origin xyz="0 0 0" rpy="0 0 0"/>
            <mass value="1" />
            <inertia ixx="100" ixy="0" ixz="0" iyy="100" iyz="0" izz="100" />
        </inertial>
        <visual>
            <origin xyz="0 0 0" rpy="0 0 0"/>
            <geometry>
                <box size="0.5 0.5 0.5" />
            </geometry>
            <material name="Cyan">
                <color rgba="0 1.0 1.0 1.0"/>
            </material>
        </visual>
        <collision>
            <origin xyz="0 0 0" rpy="0 0 0"/>
            <geometry>
                <box size="0.5 0.5 0.5" />
            </geometry>
        </collision>
    </link>
    <joint name="Torso_FrontLeftShoulder" type="revolute">
       <parent link="Torso"/>
       <child  link="FrontLeftShoulder"/>
       <origin rpy="0 0 0" xyz="0.75 0.5 1.0" />
     <axis xyz="1 0 0"/>
       <limit effort="0.0" lower="-3.14159" upper="3.14159" velocity="0.0"/>
    </joint>
    <link name="FrontLeftShoulder">
        <inertial>
            <origin xyz="0 0 0" rpy="0 0 0"/>
            <mass value="1" />
            <inertia ixx="100" ixy="0" ixz="0" iyy="100" iyz="0" izz="100" />
        </inertial>
        <visual>
            <origin xyz="0 0 0" rpy="0 0 0"/>
            <geometry>
                <box size="0.5 0.5 0.5" />
            </geometry>
            <material name="Cyan">
                <color rgba="0 1.0 1.0 1.0"/>
            </material>
        </visual>
        <collision>
            <origin xyz="0 0 0" rpy="0 0 0"/>
            <geometry>
                <box size="0.5 0.5 0.5" />
            </geometry>
        </collision>
    </link>
    <joint name="Torso_FrontRightShoulder" type="revolute">
       <parent link="Torso"/>
       <child  link="FrontRightShoulder"/>
       <origin rpy="0 0 0" xyz="0.75 -0.5 1.0" />
     <axis xyz="1 0 0"/>
       <limit effort="0.0" lower="-3.14159" upper="3.14159" velocity="0.0"/>
    </joint>
    <link name="FrontRightShoulder">
        <inertial>
            <origin xyz="0 0 0" rpy="0 0 0"/>
            <mass value="1" />
            <inertia ixx="100" ixy="0" ixz="0" iyy="100" iyz="0" izz="100" />
        </inertial>
        <visual>
            <origin xyz="0 0 0" rpy="0 0 0"/>
            <geometry>
                <box size="0.5 0.5 0.5" />
            </geometry>
            <material name="Cyan">
                <color rgba="0 1.0 1.0 1.0"/>
            </material>
        </visual>
        <collision>
            <origin xyz="0 0 0" rpy="0 0 0"/>
            <geometry>
                <box size="0.5 0.5 0.5" />
            </geometry>
        </collision>
    </link>
    <joint name="BackRightShoulder_BackRightUpperArm" type="revolute">
       <parent link="BackRightShoulder"/>
       <child  link="BackRightUpperArm"/>
       <origin rpy="0 0 0" xyz="0 0 0" />
     <axis xyz="0 1 0"/>
       <limit effort="0.0" lower="-3.14159" upper="3.14159" velocity="0.0"/>
    </joint>
    <link name="BackRightUpperArm">
        <inertial>
            <origin xyz="-0.5 -0.125 0" rpy="0 0 0"/>
            <mass value="1" />
            <inertia ixx="100" ixy="0" ixz="0" iyy="100" iyz="0" izz="100" />
        </inertial>
        <visual>
            <origin xyz="-0.5 -0.125 0" rpy="0 0 0"/>
            <geometry>
                <box size="1 0.25 0.25" />
            </geometry>
            <material name="Cyan">
                <color rgba="0 1.0 1.0 1.0"/>
            </material>
        </visual>
        <collision>
            <origin xyz="-0.5 -0.125 0" rpy="0 0 0"/>
            <geometry>
                <box size="1 0.25 0.25" />
            </geometry>
        </collision>
    </link>
    <joint name="BackLeftShoulder_BackLeftUpperArm" type="revolute">
       <parent link="BackLeftShoulder"/>
       <child  link="BackLeftUpperArm"/>
       <origin rpy="0 0 0" xyz="0 0 0" />
     <axis xyz="0 1 0"/>
       <limit effort="0.0" lower="-3.14159" upper="3.14159" velocity="0.0"/>
    </joint>
    <link name="BackLeftUpperArm">
        <inertial>
            <origin xyz="-0.5 0.125 0" rpy="0 0 0"/>
            <mass value="1" />
            <inertia ixx="100" ixy="0" ixz="0" iyy="100" iyz="0" izz="100" />
        </inertial>
        <visual>
            <origin xyz="-0.5 0.125 0" rpy="0 0 0"/>
            <geometry>
                <box size="1 0.25 0.25" />
            </geometry>
            <material name="Cyan">
                <color rgba="0 1.0 1.0 1.0"/>
            </material>
        </visual>
        <collision>
            <origin xyz="-0.5 0.125 0" rpy="0 0 0"/>
            <geometry>
                <box size="1 0.25 0.25" />
            </geometry>
        </collision>
    </link>
    <joint name="FrontRightShoulder_FrontRightUpperArm" type="revolute">
       <parent link="FrontRightShoulder"/>
       <child  link="FrontRightUpperArm"/>
       <origin rpy="0 0 0" xyz="0 0 0" />
     <axis xyz="0 1 0"/>
       <limit effort="0.0" lower="-3.14159" upper="3.14159" velocity="0.0"/>
    </joint>
    <link name="FrontRightUpperArm">
        <inertial>
            <origin xyz="-0.5 -0.125 0" rpy="0 0 0"/>
            <mass value="1" />
            <inertia ixx="100" ixy="0" ixz="0" iyy="100" iyz="0" izz="100" />
        </inertial>
        <visual>
            <origin xyz="-0.5 -0.125 0" rpy="0 0 0"/>
            <geometry>
                <box size="1 0.25 0.25" />
            </geometry>
            <material name="Cyan">
                <color rgba="0 1.0 1.0 1.0"/>
            </material>
        </visual>
        <collision>
            <origin xyz="-0.5 -0.125 0" rpy="0 0 0"/>
            <geometry>
                <box size="1 0.25 0.25" />
            </geometry>
        </collision>
    </link>
    <joint name="FrontLeftShoulder_FrontLeftUpperArm" type="revolute">
       <parent link="FrontLeftShoulder"/>
       <child  link="FrontLeftUpperArm"/>
       <origin rpy="0 0 0" xyz="0 0 0" />
     <axis xyz="0 1 0"/>
       <limit effort="0.0" lower="-3.14159" upper="3.14159" velocity="0.0"/>
    </joint>
    <link name="FrontLeftUpperArm">
        <inertial>
            <origin xyz="-0.5 0.125 0" rpy="0 0 0"/>
            <mass value="1" />
            <inertia ixx="100" ixy="0" ixz="0" iyy="100" iyz="0" izz="100" />
        </inertial>
        <visual>
            <origin xyz="-0.5 0.125 0" rpy="0 0 0"/>
            <geometry>
                <box size="1 0.25 0.25" />
            </geometry>
            <material name="Cyan">
                <color rgba="0 1.0 1.0 1.0"/>
            </material>
        </visual>
        <collision>
            <origin xyz="-0.5 0.125 0" rpy="0 0 0"/>
            <geometry>
                <box size="1 0.25 0.25" />
            </geometry>
        </collision>
    </link>
    <joint name="BackRightUpperArm_BackRightLowerArm" type="revolute">
       <parent link="BackRightUpperArm"/>
       <child  link="BackRightLowerArm"/>
       <origin rpy="0 0 0" xyz="-1 0 0" />
     <axis xyz="0 1 0"/>
       <limit effort="0.0" lower="-3.14159" upper="3.14159" velocity="0.0"/>
    </joint>
    <link name="BackRightLowerArm">
        <inertial>
            <origin xyz="0 -0.125 -0.5" rpy="0 0 0"/>
            <mass value="1" />
            <inertia ixx="100" ixy="0" ixz="0" iyy="100" iyz="0" izz="100" />
        </inertial>
        <visual>
            <origin xyz="0 -0.125 -0.5" rpy="0 0 0"/>
            <geometry>
                <box size="0.25 0.25 1" />
            </geometry>
            <material name="Cyan">
                <color rgba="0 1.0 1.0 1.0"/>
            </material>
        </visual>
        <collision>
            <origin xyz="0 -0.125 -0.5" rpy="0 0 0"/>
            <geometry>
                <box size="0.25 0.25 1" />
            </geometry>
        </collision>
    </link>
    <joint name="BackLeftUpperArm_BackLeftLowerArm" type="revolute">
       <parent link="BackLeftUpperArm"/>
       <child  link="BackLeftLowerArm"/>
       <origin rpy="0 0 0" xyz="-1 0 0" />
     <axis xyz="0 1 0"/>
       <limit effort="0.0" lower="-3.14159" upper="3.14159" velocity="0.0"/>
    </joint>
    <link name="BackLeftLowerArm">
        <inertial>
            <origin xyz="0 0.125 -0.5" rpy="0 0 0"/>
            <mass value="1" />
            <inertia ixx="100" ixy="0" ixz="0" iyy="100" iyz="0" izz="100" />
        </inertial>
        <visual>
            <origin xyz="0 0.125 -0.5" rpy="0 0 0"/>
            <geometry>
                <box size="0.25 0.25 1" />
            </geometry>
            <material name="Cyan">
                <color rgba="0 1.0 1.0 1.0"/>
            </material>
        </visual>
        <collision>
            <origin xyz="0 0.125 -0.5" rpy="0 0 0"/>
            <geometry>
                <box size="0.25 0.25 1" />
            </geometry>
        </collision>
    </link>
    <joint name="FrontRightUpperArm_FrontRightLowerArm" type="revolute">
       <parent link="FrontRightUpperArm"/>
       <child  link="FrontRightLowerArm"/>
       <origin rpy="0 0 0" xyz="-1 0 0" />
     <axis xyz="0 1 0"/>
       <limit effort="0.0" lower="-3.14159" upper="3.14159" velocity="0.0"/>
    </joint>
    <link name="FrontRightLowerArm">
        <inertial>
            <origin xyz="0 -0.125 -0.5" rpy="0 0 0"/>
            <mass value="1" />
            <inertia ixx="100" ixy="0" ixz="0" iyy="100" iyz="0" izz="100" />
        </inertial>
        <visual>
            <origin xyz="0 -0.125 -0.5" rpy="0 0 0"/>
            <geometry>
                <box size="0.25 0.25 1" />
            </geometry>
            <material name="Cyan">
                <color rgba="0 1.0 1.0 1.0"/>
            </material>
        </visual>
        <collision>
            <origin xyz="0 -0.125 -0.5" rpy="0 0 0"/>
            <geometry>
                <box size="0.25 0.25 1" />
            </geometry>
        </collision>
    </link>
    <joint name="FrontLeftUpperArm_FrontLeftLowerArm" type="revolute">
       <parent link="FrontLeftUpperArm"/>
       <child  link="FrontLeftLowerArm"/>
       <origin rpy="0 0 0" xyz="-1 0 0" />
     <axis xyz="0 1 0"/>
       <limit effort="0.0" lower="-3.14159" upper="3.14159" velocity="0.0"/>
    </joint>
    <link name="FrontLeftLowerArm">
        <inertial>
            <origin xyz="0 0.125 -0.5" rpy="0 0 0"/>
            <mass value="1" />
            <inertia ixx="100" ixy="0" ixz="0" iyy="100" iyz="0" izz="100" />
        </inertial>
        <visual>
            <origin xyz="0 0.125 -0.5" rpy="0 0 0"/>
            <geometry>
                <box size="0.25 0.25 1" />
            </geometry>
            <material name="Cyan">
                <color rgba="0 1.0 1.0 1.0"/>
            </material>
        </visual>
        <collision>
            <origin xyz="0 0.125 -0.5" rpy="0 0 0"/>
            <geometry>
                <box size="0.25 0.25 1" />
            </geometry>
        </collision>
    </link>
</robot>